<?xml version="1.0" encoding="UTF-8"?>
<!-- Generated by org.testng.reporters.JUnitReportReporter -->
<testsuite hostname="LAPTOP-RTJ3JPGR" failures="1" tests="4" name="listenerInTestNG.ListenerTestCase" time="0.137" errors="1" timestamp="2024-09-03T23:23:26 IST" skipped="1">
  <testcase classname="listenerInTestNG.ListenerTestCase" name="test4" time="0.001">
    <skipped/>
  </testcase> <!-- test4 -->
  <system-out/>
  <testcase classname="listenerInTestNG.ListenerTestCase" name="test1" time="0.013"/>
  <system-out/>
  <testcase classname="listenerInTestNG.ListenerTestCase" name="test3" time="0.119">
    <error message="Method listenerInTestNG.ListenerTestCase.test3() didn&#039;t finish within the time-out 100" type="org.testng.internal.thread.ThreadTimeoutException">
      <![CDATA[org.testng.internal.thread.ThreadTimeoutException: Method listenerInTestNG.ListenerTestCase.test3() didn't finish within the time-out 100
at java.base@17.0.10/java.lang.Thread.sleep(Native Method)
at app//listenerInTestNG.ListenerTestCase.test3(ListenerTestCase.java:21)
at java.base@17.0.10/jdk.internal.reflect.NativeMethodAccessorImpl.invoke0(Native Method)
at java.base@17.0.10/jdk.internal.reflect.NativeMethodAccessorImpl.invoke(NativeMethodAccessorImpl.java:77)
at java.base@17.0.10/jdk.internal.reflect.DelegatingMethodAccessorImpl.invoke(DelegatingMethodAccessorImpl.java:43)
at java.base@17.0.10/java.lang.reflect.Method.invoke(Method.java:568)
at app//org.testng.internal.invokers.MethodInvocationHelper.invokeMethod(MethodInvocationHelper.java:136)
at app//org.testng.internal.invokers.InvokeMethodRunnable.runOne(InvokeMethodRunnable.java:44)
at app//org.testng.internal.invokers.InvokeMethodRunnable.call(InvokeMethodRunnable.java:72)
at app//org.testng.internal.invokers.InvokeMethodRunnable.call(InvokeMethodRunnable.java:10)
at java.base@17.0.10/java.util.concurrent.FutureTask.run(FutureTask.java:264)
at java.base@17.0.10/java.util.concurrent.ThreadPoolExecutor.runWorker(ThreadPoolExecutor.java:1136)
at java.base@17.0.10/java.util.concurrent.ThreadPoolExecutor$Worker.run(ThreadPoolExecutor.java:635)
at java.base@17.0.10/java.lang.Thread.run(Thread.java:840)
]]>
    </error>
  </testcase> <!-- test3 -->
  <system-out/>
  <testcase classname="listenerInTestNG.ListenerTestCase" name="test2" time="0.004">
    <failure message="expected [true] but found [false]" type="java.lang.AssertionError">
      <![CDATA[java.lang.AssertionError: expected [true] but found [false]
at org.testng.Assert.fail(Assert.java:110)
at org.testng.Assert.failNotEquals(Assert.java:1413)
at org.testng.Assert.assertTrue(Assert.java:56)
at org.testng.Assert.assertTrue(Assert.java:66)
at listenerInTestNG.ListenerTestCase.test2(ListenerTestCase.java:17)
at java.base/jdk.internal.reflect.NativeMethodAccessorImpl.invoke0(Native Method)
at java.base/jdk.internal.reflect.NativeMethodAccessorImpl.invoke(NativeMethodAccessorImpl.java:77)
at java.base/jdk.internal.reflect.DelegatingMethodAccessorImpl.invoke(DelegatingMethodAccessorImpl.java:43)
at java.base/java.lang.reflect.Method.invoke(Method.java:568)
at org.testng.internal.invokers.MethodInvocationHelper.invokeMethod(MethodInvocationHelper.java:136)
at org.testng.internal.invokers.TestInvoker.invokeMethod(TestInvoker.java:658)
at org.testng.internal.invokers.TestInvoker.invokeTestMethod(TestInvoker.java:219)
at org.testng.internal.invokers.MethodRunner.runInSequence(MethodRunner.java:50)
at org.testng.internal.invokers.TestInvoker$MethodInvocationAgent.invoke(TestInvoker.java:923)
at org.testng.internal.invokers.TestInvoker.invokeTestMethods(TestInvoker.java:192)
at org.testng.internal.invokers.TestMethodWorker.invokeTestMethods(TestMethodWorker.java:146)
at org.testng.internal.invokers.TestMethodWorker.run(TestMethodWorker.java:128)
at java.base/java.util.ArrayList.forEach(ArrayList.java:1511)
at org.testng.TestRunner.privateRun(TestRunner.java:808)
at org.testng.TestRunner.run(TestRunner.java:603)
at org.testng.SuiteRunner.runTest(SuiteRunner.java:429)
at org.testng.SuiteRunner.runSequentially(SuiteRunner.java:423)
at org.testng.SuiteRunner.privateRun(SuiteRunner.java:383)
at org.testng.SuiteRunner.run(SuiteRunner.java:326)
at org.testng.SuiteRunnerWorker.runSuite(SuiteRunnerWorker.java:52)
at org.testng.SuiteRunnerWorker.run(SuiteRunnerWorker.java:95)
at org.testng.TestNG.runSuitesSequentially(TestNG.java:1249)
at org.testng.TestNG.runSuitesLocally(TestNG.java:1169)
at org.testng.TestNG.runSuites(TestNG.java:1092)
at org.testng.TestNG.run(TestNG.java:1060)
at org.testng.remote.AbstractRemoteTestNG.run(AbstractRemoteTestNG.java:115)
at org.testng.remote.RemoteTestNG.initAndRun(RemoteTestNG.java:293)
at org.testng.remote.RemoteTestNG.main(RemoteTestNG.java:91)
]]>
    </failure>
  </testcase> <!-- test2 -->
  <system-out/>
</testsuite> <!-- listenerInTestNG.ListenerTestCase -->
